Workbook

Sheet Import-user
A1: Import Users
J2: Standard Clearances
J3: Administrator : | K3: GroupEverythingSecurityId
J4: Supervisor : | K4: GroupSupervisorSecurityId
J5: Default User : | K5: GroupUserSecurityId
J6: Drive App User : | K6: GroupDriveUserSecurityId
J7: View Only : | K7: GroupViewOnlySecurityId | N7: Phone number formatting example: +1 5555555555
D8: As the final validation happens when the "import users" button is clicked please ensure that it's not a common password e.g. test1234 | J8: Nothing : | K8: GroupNothingSecurityId | N8: Phone number extensions cannot exceed five characters and must contain only digits. | V8: HOS Fields
A10: Username (must be a single word or a valid email) | B10: First Name | C10: Last Name | D10: Password (minimum of 8 characters) | E10: Password Validation | F10: Group Name(s) (Names of groups separated by the | character. E.g. Drivers|West|Garmin) | G10: Groups | H10: Reporting Group Name(s) (Names of reporting groups separated by the | character. E.g. Drivers|West|Garmin) | I10: Reporting Groups | J10: Security Clearance ID | K10: Driver Key (optional) : NFC Key Number | L10: Driver Key (optional) : Custom NFC Key Number | M10: Country Code | N10: Phone Number (Needs country phone code and a space inbetween) | O10: Phone Number Extension | P10: Designation | Q10: Employee Number | R10: Fuel Economy Measurement | S10: Distance Measurement System | T10: Feature Preview On : true Off : false | U10: Time Zone | V10: Authority Name | W10: Authority Address | X10: Carrier Number | Y10: Home Terminal | Z10: Home Terminal Address | AA10: Driver License Number | AB10: License State/Province | AC10: Ruleset (select the ruleset from the dropdown) | AD10: Yard Move Allowed On : true Off : false | AE10: Personal Conveyance On : true Off : false | AF10: Is Driver true or false | AG10: Password Validation for First Name | AH10: Password Validation for Last Name | AI10: Password Validation for Username | AJ10: Validation | AK10: Data to Import
E11: =IF(AND(A11="",D11=""),"",IF(OR(AND(ISNUMBER(SEARCH("@",A11))*ISNUMBER(SEARCH(".",A11,SEARCH("@",A11))),ISBLANK(D11)),LEN(D11)>=8),1,0)) | G11: =IF(F11="","",F11) | I11: =IF(H11="","",H11) | AG11: =IF(ISNUMBER(SEARCH(B11,D11)), 0, 1) -> 1 | AH11: =IF(ISNUMBER(SEARCH(C11,D11)), 0, 1) -> 1 | AI11: =IF(ISNUMBER(SEARCH(A11,D11)), 0, 1) -> 1 | AJ11: =IF(A11="","User Name Missing",IF(B11="","First Name Missing",IF(C11="","Last Name Missing",IF(E11=0,"Password Short(Min 8 Charcters)",IF(AG11=0,"The password cannot contain the user's first name.",IF(AH11=0,"The password cannot contain the user's last name.",IF(AI11=0,"The password cannot contain the username.",IF(F11="","Group Missing",IF(J11="","Security Clearance Missing",IF(R11="","Fuel Economy Measurement missing",IF(S11="","Distance Measurement System missing",IF(T11="","Feature Preview missing",IF(U11="","Time Zone Missing",IF(AD11="","Yard Move allowed Missing",IF(AE11="","Personal Conveyance Missing","Good"))))))))))))))) -> User Name Missing | AK11: =IF(AJ11<>"Good","",A11&","&B11&","&C11&","&D11&","&F11&","&H11&","&J11&","&K11&","&L11&","&M11&","&N11&","&O11&","&P11&","&Q11&","&IF(R11<>"",VLOOKUP(R11,'Vlookup''sRef'!$C$3:$D$6,2,FALSE()),"")&","&IF(S11<>"",VLOOKUP(S11,'Vlookup''sRef'!$F$3:$G$4,2,FALSE()),"")&","&T11&","&U11&","&V11&","&W11&","&X11&","&Y11&","&Z11&","&AA11&","&IF(AB11<>"",VLOOKUP(AB11,'Vlookup''sRef'!$O$2:$P$101,2,FALSE()),"")&","&IF(AC11<>"",VLOOKUP(AC11,RulesetRef!$A$2:$B$95,2,FALSE()),"")&","&AD11&","&AE11&","&IF(AF11<>"",AF11,"false"))
E12: =IF(AND(A12="",D12=""),"",IF(OR(AND(ISNUMBER(SEARCH("@",A12))*ISNUMBER(SEARCH(".",A12,SEARCH("@",A12))),ISBLANK(D12)),LEN(D12)>=8),1,0)) | G12: =IF(F12="","",F12) | I12: =IF(H12="","",H12) | AG12: =IF(ISNUMBER(SEARCH(B12,D12)), 0, 1) -> 1 | AH12: =IF(ISNUMBER(SEARCH(C12,D12)), 0, 1) -> 1 | AI12: =IF(ISNUMBER(SEARCH(A12,D12)), 0, 1) -> 1 | AJ12: =IF(A12="","User Name Missing",IF(B12="","First Name Missing",IF(C12="","Last Name Missing",IF(E12=0,"Password Short(Min 8 Charcters)",IF(AG12=0,"The password cannot contain the user's first name.",IF(AH12=0,"The password cannot contain the user's last name.",IF(AI12=0,"The password cannot contain the username.",IF(F12="","Group Missing",IF(J12="","Security Clearance Missing",IF(R12="","Fuel Economy Measurement missing",IF(S12="","Distance Measurement System missing",IF(T12="","Feature Preview missing",IF(U12="","Time Zone Missing",IF(AD12="","Yard Move allowed Missing",IF(AE12="","Personal Conveyance Missing","Good"))))))))))))))) -> User Name Missing | AK12: =IF(AJ12<>"Good","",A12&","&B12&","&C12&","&D12&","&F12&","&H12&","&J12&","&K12&","&L12&","&M12&","&N12&","&O12&","&P12&","&Q12&","&IF(R12<>"",VLOOKUP(R12,'Vlookup''sRef'!$C$3:$D$6,2,FALSE()),"")&","&IF(S12<>"",VLOOKUP(S12,'Vlookup''sRef'!$F$3:$G$4,2,FALSE()),"")&","&T12&","&U12&","&V12&","&W12&","&X12&","&Y12&","&Z12&","&AA12&","&IF(AB12<>"",VLOOKUP(AB12,'Vlookup''sRef'!$O$2:$P$101,2,FALSE()),"")&","&IF(AC12<>"",VLOOKUP(AC12,RulesetRef!$A$2:$B$95,2,FALSE()),"")&","&AD12&","&AE12&","&IF(AF12<>"",AF12,"false"))
E13: =IF(AND(A13="",D13=""),"",IF(OR(AND(ISNUMBER(SEARCH("@",A13))*ISNUMBER(SEARCH(".",A13,SEARCH("@",A13))),ISBLANK(D13)),LEN(D13)>=8),1,0)) | G13: =IF(F13="","",F13) | I13: =IF(H13="","",H13) | AG13: =IF(ISNUMBER(SEARCH(B13,D13)), 0, 1) -> 1 | AH13: =IF(ISNUMBER(SEARCH(C13,D13)), 0, 1) -> 1 | AI13: =IF(ISNUMBER(SEARCH(A13,D13)), 0, 1) -> 1 | AJ13: =IF(A13="","User Name Missing",IF(B13="","First Name Missing",IF(C13="","Last Name Missing",IF(E13=0,"Password Short(Min 8 Charcters)",IF(AG13=0,"The password cannot contain the user's first name.",IF(AH13=0,"The password cannot contain the user's last name.",IF(AI13=0,"The password cannot contain the username.",IF(F13="","Group Missing",IF(J13="","Security Clearance Missing",IF(R13="","Fuel Economy Measurement missing",IF(S13="","Distance Measurement System missing",IF(T13="","Feature Preview missing",IF(U13="","Time Zone Missing",IF(AD13="","Yard Move allowed Missing",IF(AE13="","Personal Conveyance Missing","Good"))))))))))))))) -> User Name Missing | AK13: =IF(AJ13<>"Good","",A13&","&B13&","&C13&","&D13&","&F13&","&H13&","&J13&","&K13&","&L13&","&M13&","&N13&","&O13&","&P13&","&Q13&","&IF(R13<>"",VLOOKUP(R13,'Vlookup''sRef'!$C$3:$D$6,2,FALSE()),"")&","&IF(S13<>"",VLOOKUP(S13,'Vlookup''sRef'!$F$3:$G$4,2,FALSE()),"")&","&T13&","&U13&","&V13&","&W13&","&X13&","&Y13&","&Z13&","&AA13&","&IF(AB13<>"",VLOOKUP(AB13,'Vlookup''sRef'!$O$2:$P$101,2,FALSE()),"")&","&IF(AC13<>"",VLOOKUP(AC13,RulesetRef!$A$2:$B$95,2,FALSE()),"")&","&AD13&","&AE13&","&IF(AF13<>"",AF13,"false"))
E14: =IF(AND(A14="",D14=""),"",IF(OR(AND(ISNUMBER(SEARCH("@",A14))*ISNUMBER(SEARCH(".",A14,SEARCH("@",A14))),ISBLANK(D14)),LEN(D14)>=8),1,0)) | G14: =IF(F14="","",F14) | I14: =IF(H14="","",H14) | AG14: =IF(ISNUMBER(SEARCH(B14,D14)), 0, 1) -> 1 | AH14: =IF(ISNUMBER(SEARCH(C14,D14)), 0, 1) -> 1 | AI14: =IF(ISNUMBER(SEARCH(A14,D14)), 0, 1) -> 1 | AJ14: =IF(A14="","User Name Missing",IF(B14="","First Name Missing",IF(C14="","Last Name Missing",IF(E14=0,"Password Short(Min 8 Charcters)",IF(AG14=0,"The password cannot contain the user's first name.",IF(AH14=0,"The password cannot contain the user's last name.",IF(AI14=0,"The password cannot contain the username.",IF(F14="","Group Missing",IF(J14="","Security Clearance Missing",IF(R14="","Fuel Economy Measurement missing",IF(S14="","Distance Measurement System missing",IF(T14="","Feature Preview missing",IF(U14="","Time Zone Missing",IF(AD14="","Yard Move allowed Missing",IF(AE14="","Personal Conveyance Missing","Good"))))))))))))))) -> User Name Missing | AK14: =IF(AJ14<>"Good","",A14&","&B14&","&C14&","&D14&","&F14&","&H14&","&J14&","&K14&","&L14&","&M14&","&N14&","&O14&","&P14&","&Q14&","&IF(R14<>"",VLOOKUP(R14,'Vlookup''sRef'!$C$3:$D$6,2,FALSE()),"")&","&IF(S14<>"",VLOOKUP(S14,'Vlookup''sRef'!$F$3:$G$4,2,FALSE()),"")&","&T14&","&U14&","&V14&","&W14&","&X14&","&Y14&","&Z14&","&AA14&","&IF(AB14<>"",VLOOKUP(AB14,'Vlookup''sRef'!$O$2:$P$101,2,FALSE()),"")&","&IF(AC14<>"",VLOOKUP(AC14,RulesetRef!$A$2:$B$95,2,FALSE()),"")&","&AD14&","&AE14&","&IF(AF14<>"",AF14,"false"))
E15: =IF(AND(A15="",D15=""),"",IF(OR(AND(ISNUMBER(SEARCH("@",A15))*ISNUMBER(SEARCH(".",A15,SEARCH("@",A15))),ISBLANK(D15)),LEN(D15)>=8),1,0)) | G15: =IF(F15="","",F15) | I15: =IF(H15="","",H15) | AG15: =IF(ISNUMBER(SEARCH(B15,D15)), 0, 1) -> 1 | AH15: =IF(ISNUMBER(SEARCH(C15,D15)), 0, 1) -> 1 | AI15: =IF(ISNUMBER(SEARCH(A15,D15)), 0, 1) -> 1 | AJ15: =IF(A15="","User Name Missing",IF(B15="","First Name Missing",IF(C15="","Last Name Missing",IF(E15=0,"Password Short(Min 8 Charcters)",IF(AG15=0,"The password cannot contain the user's first name.",IF(AH15=0,"The password cannot contain the user's last name.",IF(AI15=0,"The password cannot contain the username.",IF(F15="","Group Missing",IF(J15="","Security Clearance Missing",IF(R15="","Fuel Economy Measurement missing",IF(S15="","Distance Measurement System missing",IF(T15="","Feature Preview missing",IF(U15="","Time Zone Missing",IF(AD15="","Yard Move allowed Missing",IF(AE15="","Personal Conveyance Missing","Good"))))))))))))))) -> User Name Missing | AK15: =IF(AJ15<>"Good","",A15&","&B15&","&C15&","&D15&","&F15&","&H15&","&J15&","&K15&","&L15&","&M15&","&N15&","&O15&","&P15&","&Q15&","&IF(R15<>"",VLOOKUP(R15,'Vlookup''sRef'!$C$3:$D$6,2,FALSE()),"")&","&IF(S15<>"",VLOOKUP(S15,'Vlookup''sRef'!$F$3:$G$4,2,FALSE()),"")&","&T15&","&U15&","&V15&","&W15&","&X15&","&Y15&","&Z15&","&AA15&","&IF(AB15<>"",VLOOKUP(AB15,'Vlookup''sRef'!$O$2:$P$101,2,FALSE()),"")&","&IF(AC15<>"",VLOOKUP(AC15,RulesetRef!$A$2:$B$95,2,FALSE()),"")&","&AD15&","&AE15&","&IF(AF15<>"",AF15,"false"))
E16: =IF(AND(A16="",D16=""),"",IF(OR(AND(ISNUMBER(SEARCH("@",A16))*ISNUMBER(SEARCH(".",A16,SEARCH("@",A16))),ISBLANK(D16)),LEN(D16)>=8),1,0)) | G16: =IF(F16="","",F16) | I16: =IF(H16="","",H16) | AG16: =IF(ISNUMBER(SEARCH(B16,D16)), 0, 1) -> 1 | AH16: =IF(ISNUMBER(SEARCH(C16,D16)), 0, 1) -> 1 | AI16: =IF(ISNUMBER(SEARCH(A16,D16)), 0, 1) -> 1 | AJ16: =IF(A16="","User Name Missing",IF(B16="","First Name Missing",IF(C16="","Last Name Missing",IF(E16=0,"Password Short(Min 8 Charcters)",IF(AG16=0,"The password cannot contain the user's first name.",IF(AH16=0,"The password cannot contain the user's last name.",IF(AI16=0,"The password cannot contain the username.",IF(F16="","Group Missing",IF(J16="","Security Clearance Missing",IF(R16="","Fuel Economy Measurement missing",IF(S16="","Distance Measurement System missing",IF(T16="","Feature Preview missing",IF(U16="","Time Zone Missing",IF(AD16="","Yard Move allowed Missing",IF(AE16="","Personal Conveyance Missing","Good"))))))))))))))) -> User Name Missing | AK16: =IF(AJ16<>"Good","",A16&","&B16&","&C16&","&D16&","&F16&","&H16&","&J16&","&K16&","&L16&","&M16&","&N16&","&O16&","&P16&","&Q16&","&IF(R16<>"",VLOOKUP(R16,'Vlookup''sRef'!$C$3:$D$6,2,FALSE()),"")&","&IF(S16<>"",VLOOKUP(S16,'Vlookup''sRef'!$F$3:$G$4,2,FALSE()),"")&","&T16&","&U16&","&V16&","&W16&","&X16&","&Y16&","&Z16&","&AA16&","&IF(AB16<>"",VLOOKUP(AB16,'Vlookup''sRef'!$O$2:$P$101,2,FALSE()),"")&","&IF(AC16<>"",VLOOKUP(AC16,RulesetRef!$A$2:$B$95,2,FALSE()),"")&","&AD16&","&AE16&","&IF(AF16<>"",AF16,"false"))
E17: =IF(AND(A17="",D17=""),"",IF(OR(AND(ISNUMBER(SEARCH("@",A17))*ISNUMBER(SEARCH(".",A17,SEARCH("@",A17))),ISBLANK(D17)),LEN(D17)>=8),1,0)) | G17: =IF(F17="","",F17) | I17: =IF(H17="","",H17) | AG17: =IF(ISNUMBER(SEARCH(B17,D17)), 0, 1) -> 1 | AH17: =IF(ISNUMBER(SEARCH(C17,D17)), 0, 1) -> 1 | AI17: =IF(ISNUMBER(SEARCH(A17,D17)), 0, 1) -> 1 | AJ17: =IF(A17="","User Name Missing",IF(B17="","First Name Missing",IF(C17="","Last Name Missing",IF(E17=0,"Password Short(Min 8 Charcters)",IF(AG17=0,"The password cannot contain the user's first name.",IF(AH17=0,"The password cannot contain the user's last name.",IF(AI17=0,"The password cannot contain the username.",IF(F17="","Group Missing",IF(J17="","Security Clearance Missing",IF(R17="","Fuel Economy Measurement missing",IF(S17="","Distance Measurement System missing",IF(T17="","Feature Preview missing",IF(U17="","Time Zone Missing",IF(AD17="","Yard Move allowed Missing",IF(AE17="","Personal Conveyance Missing","Good"))))))))))))))) -> User Name Missing | AK17: =IF(AJ17<>"Good","",A17&","&B17&","&C17&","&D17&","&F17&","&H17&","&J17&","&K17&","&L17&","&M17&","&N17&","&O17&","&P17&","&Q17&","&IF(R17<>"",VLOOKUP(R17,'Vlookup''sRef'!$C$3:$D$6,2,FALSE()),"")&","&IF(S17<>"",VLOOKUP(S17,'Vlookup''sRef'!$F$3:$G$4,2,FALSE()),"")&","&T17&","&U17&","&V17&","&W17&","&X17&","&Y17&","&Z17&","&AA17&","&IF(AB17<>"",VLOOKUP(AB17,'Vlookup''sRef'!$O$2:$P$101,2,FALSE()),"")&","&IF(AC17<>"",VLOOKUP(AC17,RulesetRef!$A$2:$B$95,2,FALSE()),"")&","&AD17&","&AE17&","&IF(AF17<>"",AF17,"false"))
E18: =IF(AND(A18="",D18=""),"",IF(OR(AND(ISNUMBER(SEARCH("@",A18))*ISNUMBER(SEARCH(".",A18,SEARCH("@",A18))),ISBLANK(D18)),LEN(D18)>=8),1,0)) | G18: =IF(F18="","",F18) | I18: =IF(H18="","",H18) | AG18: =IF(ISNUMBER(SEARCH(B18,D18)), 0, 1) -> 1 | AH18: =IF(ISNUMBER(SEARCH(C18,D18)), 0, 1) -> 1 | AI18: =IF(ISNUMBER(SEARCH(A18,D18)), 0, 1) -> 1 | AJ18: =IF(A18="","User Name Missing",IF(B18="","First Name Missing",IF(C18="","Last Name Missing",IF(E18=0,"Password Short(Min 8 Charcters)",IF(AG18=0,"The password cannot contain the user's first name.",IF(AH18=0,"The password cannot contain the user's last name.",IF(AI18=0,"The password cannot contain the username.",IF(F18="","Group Missing",IF(J18="","Security Clearance Missing",IF(R18="","Fuel Economy Measurement missing",IF(S18="","Distance Measurement System missing",IF(T18="","Feature Preview missing",IF(U18="","Time Zone Missing",IF(AD18="","Yard Move allowed Missing",IF(AE18="","Personal Conveyance Missing","Good"))))))))))))))) -> User Name Missing | AK18: =IF(AJ18<>"Good","",A18&","&B18&","&C18&","&D18&","&F18&","&H18&","&J18&","&K18&","&L18&","&M18&","&N18&","&O18&","&P18&","&Q18&","&IF(R18<>"",VLOOKUP(R18,'Vlookup''sRef'!$C$3:$D$6,2,FALSE()),"")&","&IF(S18<>"",VLOOKUP(S18,'Vlookup''sRef'!$F$3:$G$4,2,FALSE()),"")&","&T18&","&U18&","&V18&","&W18&","&X18&","&Y18&","&Z18&","&AA18&","&IF(AB18<>"",VLOOKUP(AB18,'Vlookup''sRef'!$O$2:$P$101,2,FALSE()),"")&","&IF(AC18<>"",VLOOKUP(AC18,RulesetRef!$A$2:$B$95,2,FALSE()),"")&","&AD18&","&AE18&","&IF(AF18<>"",AF18,"false"))
E19: =IF(AND(A19="",D19=""),"",IF(OR(AND(ISNUMBER(SEARCH("@",A19))*ISNUMBER(SEARCH(".",A19,SEARCH("@",A19))),ISBLANK(D19)),LEN(D19)>=8),1,0)) | G19: =IF(F19="","",F19) | I19: =IF(H19="","",H19) | AG19: =IF(ISNUMBER(SEARCH(B19,D19)), 0, 1) -> 1 | AH19: =IF(ISNUMBER(SEARCH(C19,D19)), 0, 1) -> 1 | AI19: =IF(ISNUMBER(SEARCH(A19,D19)), 0, 1) -> 1 | AJ19: =IF(A19="","User Name Missing",IF(B19="","First Name Missing",IF(C19="","Last Name Missing",IF(E19=0,"Password Short(Min 8 Charcters)",IF(AG19=0,"The password cannot contain the user's first name.",IF(AH19=0,"The password cannot contain the user's last name.",IF(AI19=0,"The password cannot contain the username.",IF(F19="","Group Missing",IF(J19="","Security Clearance Missing",IF(R19="","Fuel Economy Measurement missing",IF(S19="","Distance Measurement System missing",IF(T19="","Feature Preview missing",IF(U19="","Time Zone Missing",IF(AD19="","Yard Move allowed Missing",IF(AE19="","Personal Conveyance Missing","Good"))))))))))))))) -> User Name Missing | AK19: =IF(AJ19<>"Good","",A19&","&B19&","&C19&","&D19&","&F19&","&H19&","&J19&","&K19&","&L19&","&M19&","&N19&","&O19&","&P19&","&Q19&","&IF(R19<>"",VLOOKUP(R19,'Vlookup''sRef'!$C$3:$D$6,2,FALSE()),"")&","&IF(S19<>"",VLOOKUP(S19,'Vlookup''sRef'!$F$3:$G$4,2,FALSE()),"")&","&T19&","&U19&","&V19&","&W19&","&X19&","&Y19&","&Z19&","&AA19&","&IF(AB19<>"",VLOOKUP(AB19,'Vlookup''sRef'!$O$2:$P$101,2,FALSE()),"")&","&IF(AC19<>"",VLOOKUP(AC19,RulesetRef!$A$2:$B$95,2,FALSE()),"")&","&AD19&","&AE19&","&IF(AF19<>"",AF19,"false"))
E20: =IF(AND(A20="",D20=""),"",IF(OR(AND(ISNUMBER(SEARCH("@",A20))*ISNUMBER(SEARCH(".",A20,SEARCH("@",A20))),ISBLANK(D20)),LEN(D20)>=8),1,0)) | G20: =IF(F20="","",F20) | I20: =IF(H20="","",H20) | AG20: =IF(ISNUMBER(SEARCH(B20,D20)), 0, 1) -> 1 | AH20: =IF(ISNUMBER(SEARCH(C20,D20)), 0, 1) -> 1 | AI20: =IF(ISNUMBER(SEARCH(A20,D20)), 0, 1) -> 1 | AJ20: =IF(A20="","User Name Missing",IF(B20="","First Name Missing",IF(C20="","Last Name Missing",IF(E20=0,"Password Short(Min 8 Charcters)",IF(AG20=0,"The password cannot contain the user's first name.",IF(AH20=0,"The password cannot contain the user's last name.",IF(AI20=0,"The password cannot contain the username.",IF(F20="","Group Missing",IF(J20="","Security Clearance Missing",IF(R20="","Fuel Economy Measurement missing",IF(S20="","Distance Measurement System missing",IF(T20="","Feature Preview missing",IF(U20="","Time Zone Missing",IF(AD20="","Yard Move allowed Missing",IF(AE20="","Personal Conveyance Missing","Good"))))))))))))))) -> User Name Missing | AK20: =IF(AJ20<>"Good","",A20&","&B20&","&C20&","&D20&","&F20&","&H20&","&J20&","&K20&","&L20&","&M20&","&N20&","&O20&","&P20&","&Q20&","&IF(R20<>"",VLOOKUP(R20,'Vlookup''sRef'!$C$3:$D$6,2,FALSE()),"")&","&IF(S20<>"",VLOOKUP(S20,'Vlookup''sRef'!$F$3:$G$4,2,FALSE()),"")&","&T20&","&U20&","&V20&","&W20&","&X20&","&Y20&","&Z20&","&AA20&","&IF(AB20<>"",VLOOKUP(AB20,'Vlookup''sRef'!$O$2:$P$101,2,FALSE()),"")&","&IF(AC20<>"",VLOOKUP(AC20,RulesetRef!$A$2:$B$95,2,FALSE()),"")&","&AD20&","&AE20&","&IF(AF20<>"",AF20,"false"))
E21: =IF(AND(A21="",D21=""),"",IF(OR(AND(ISNUMBER(SEARCH("@",A21))*ISNUMBER(SEARCH(".",A21,SEARCH("@",A21))),ISBLANK(D21)),LEN(D21)>=8),1,0)) | G21: =IF(F21="","",F21) | I21: =IF(H21="","",H21) | AG21: =IF(ISNUMBER(SEARCH(B21,D21)), 0, 1) -> 1 | AH21: =IF(ISNUMBER(SEARCH(C21,D21)), 0, 1) -> 1 | AI21: =IF(ISNUMBER(SEARCH(A21,D21)), 0, 1) -> 1 | AJ21: =IF(A21="","User Name Missing",IF(B21="","First Name Missing",IF(C21="","Last Name Missing",IF(E21=0,"Password Short(Min 8 Charcters)",IF(AG21=0,"The password cannot contain the user's first name.",IF(AH21=0,"The password cannot contain the user's last name.",IF(AI21=0,"The password cannot contain the username.",IF(F21="","Group Missing",IF(J21="","Security Clearance Missing",IF(R21="","Fuel Economy Measurement missing",IF(S21="","Distance Measurement System missing",IF(T21="","Feature Preview missing",IF(U21="","Time Zone Missing",IF(AD21="","Yard Move allowed Missing",IF(AE21="","Personal Conveyance Missing","Good"))))))))))))))) -> User Name Missing | AK21: =IF(AJ21<>"Good","",A21&","&B21&","&C21&","&D21&","&F21&","&H21&","&J21&","&K21&","&L21&","&M21&","&N21&","&O21&","&P21&","&Q21&","&IF(R21<>"",VLOOKUP(R21,'Vlookup''sRef'!$C$3:$D$6,2,FALSE()),"")&","&IF(S21<>"",VLOOKUP(S21,'Vlookup''sRef'!$F$3:$G$4,2,FALSE()),"")&","&T21&","&U21&","&V21&","&W21&","&X21&","&Y21&","&Z21&","&AA21&","&IF(AB21<>"",VLOOKUP(AB21,'Vlookup''sRef'!$O$2:$P$101,2,FALSE()),"")&","&IF(AC21<>"",VLOOKUP(AC21,RulesetRef!$A$2:$B$95,2,FALSE()),"")&","&AD21&","&AE21&","&IF(AF21<>"",AF21,"false"))
E22: =IF(AND(A22="",D22=""),"",IF(OR(AND(ISNUMBER(SEARCH("@",A22))*ISNUMBER(SEARCH(".",A22,SEARCH("@",A22))),ISBLANK(D22)),LEN(D22)>=8),1,0)) | G22: =IF(F22="","",F22) | I22: =IF(H22="","",H22) | AG22: =IF(ISNUMBER(SEARCH(B22,D22)), 0, 1) -> 1 | AH22: =IF(ISNUMBER(SEARCH(C22,D22)), 0, 1) -> 1 | AI22: =IF(ISNUMBER(SEARCH(A22,D22)), 0, 1) -> 1 | AJ22: =IF(A22="","User Name Missing",IF(B22="","First Name Missing",IF(C22="","Last Name Missing",IF(E22=0,"Password Short(Min 8 Charcters)",IF(AG22=0,"The password cannot contain the user's first name.",IF(AH22=0,"The password cannot contain the user's last name.",IF(AI22=0,"The password cannot contain the username.",IF(F22="","Group Missing",IF(J22="","Security Clearance Missing",IF(R22="","Fuel Economy Measurement missing",IF(S22="","Distance Measurement System missing",IF(T22="","Feature Preview missing",IF(U22="","Time Zone Missing",IF(AD22="","Yard Move allowed Missing",IF(AE22="","Personal Conveyance Missing","Good"))))))))))))))) -> User Name Missing | AK22: =IF(AJ22<>"Good","",A22&","&B22&","&C22&","&D22&","&F22&","&H22&","&J22&","&K22&","&L22&","&M22&","&N22&","&O22&","&P22&","&Q22&","&IF(R22<>"",VLOOKUP(R22,'Vlookup''sRef'!$C$3:$D$6,2,FALSE()),"")&","&IF(S22<>"",VLOOKUP(S22,'Vlookup''sRef'!$F$3:$G$4,2,FALSE()),"")&","&T22&","&U22&","&V22&","&W22&","&X22&","&Y22&","&Z22&","&AA22&","&IF(AB22<>"",VLOOKUP(AB22,'Vlookup''sRef'!$O$2:$P$101,2,FALSE()),"")&","&IF(AC22<>"",VLOOKUP(AC22,RulesetRef!$A$2:$B$95,2,FALSE()),"")&","&AD22&","&AE22&","&IF(AF22<>"",AF22,"false"))
... E3281: =IF(AND(A3281="",D3281=""),"",IF(OR(AND(ISNUMBER(SEARCH("@",A3281))*ISNUMBER(SEARCH(".",A3281,SEARCH("@",A3281))),ISBLANK(D3281)),LEN(D3281)>=8),1,0)) | G3281: =IF(F3281="","",F3281) | I3281: =IF(H3281="","",H3281) | AG3281: =IF(ISNUMBER(SEARCH(B3281,D3281)), 0, 1) -> 1 | AH3281: =IF(ISNUMBER(SEARCH(C3281,D3281)), 0, 1) -> 1 | AI3281: =IF(ISNUMBER(SEARCH(A3281,D3281)), 0, 1) -> 1 | AJ3281: =IF(A3281="","User Name Missing",IF(B3281="","First Name Missing",IF(C3281="","Last Name Missing",IF(E3281=0,"Password Short(Min 8 Charcters)",IF(AG3281=0,"The password cannot contain the user's first name.",IF(AH3281=0,"The password cannot contain the user's last name.",IF(AI3281=0,"The password cannot contain the username.",IF(F3281="","Group Missing",IF(J3281="","Security Clearance Missing",IF(R3281="","Fuel Economy Measurement missing",IF(S3281="","Distance Measurement System missing",IF(T3281="","Feature Preview missing",IF(U3281="","Time Zone Missing",IF(AD3281="","Yard Move allowed Missing",IF(AE3281="","Personal Conveyance Missing","Good"))))))))))))))) -> User Name Missing | AK3281: =IF(AJ3281<>"Good","",A3281&","&B3281&","&C3281&","&D3281&","&F3281&","&H3281&","&J3281&","&K3281&","&L3281&","&M3281&","&N3281&","&O3281&","&P3281&","&Q3281&","&IF(R3281<>"",VLOOKUP(R3281,'Vlookup''sRef'!$C$3:$D$6,2,FALSE()),"")&","&IF(S3281<>"",VLOOKUP(S3281,'Vlookup''sRef'!$F$3:$G$4,2,FALSE()),"")&","&T3281&","&U3281&","&V3281&","&W3281&","&X3281&","&Y3281&","&Z3281&","&AA3281&","&IF(AB3281<>"",VLOOKUP(AB3281,'Vlookup''sRef'!$O$2:$P$101,2,FALSE()),"")&","&IF(AC3281<>"",VLOOKUP(AC3281,RulesetRef!$A$2:$B$95,2,FALSE()),"")&","&AD3281&","&AE3281&","&IF(AF3281<>"",AF3281,"false"))
E3282: =IF(AND(A3282="",D3282=""),"",IF(OR(AND(ISNUMBER(SEARCH("@",A3282))*ISNUMBER(SEARCH(".",A3282,SEARCH("@",A3282))),ISBLANK(D3282)),LEN(D3282)>=8),1,0)) | I3282: =IF(H3282="","",H3282) | AG3282: =IF(ISNUMBER(SEARCH(B3282,D3282)), 0, 1) -> 1 | AH3282: =IF(ISNUMBER(SEARCH(C3282,D3282)), 0, 1) -> 1 | AI3282: =IF(ISNUMBER(SEARCH(A3282,D3282)), 0, 1) -> 1 | AJ3282: =IF(A3282="","User Name Missing",IF(B3282="","First Name Missing",IF(C3282="","Last Name Missing",IF(E3282=0,"Password Short(Min 8 Charcters)",IF(AG3282=0,"The password cannot contain the user's first name.",IF(AH3282=0,"The password cannot contain the user's last name.",IF(AI3282=0,"The password cannot contain the username.",IF(F3282="","Group Missing",IF(J3282="","Security Clearance Missing",IF(R3282="","Fuel Economy Measurement missing",IF(S3282="","Distance Measurement System missing",IF(T3282="","Feature Preview missing",IF(U3282="","Time Zone Missing",IF(AD3282="","Yard Move allowed Missing",IF(AE3282="","Personal Conveyance Missing","Good"))))))))))))))) -> User Name Missing | AK3282: =IF(AJ3282<>"Good","",A3282&","&B3282&","&C3282&","&D3282&","&F3282&","&H3282&","&J3282&","&K3282&","&L3282&","&M3282&","&N3282&","&O3282&","&P3282&","&Q3282&","&IF(R3282<>"",VLOOKUP(R3282,'Vlookup''sRef'!$C$3:$D$6,2,FALSE()),"")&","&IF(S3282<>"",VLOOKUP(S3282,'Vlookup''sRef'!$F$3:$G$4,2,FALSE()),"")&","&T3282&","&U3282&","&V3282&","&W3282&","&X3282&","&Y3282&","&Z3282&","&AA3282&","&IF(AB3282<>"",VLOOKUP(AB3282,'Vlookup''sRef'!$O$2:$P$101,2,FALSE()),"")&","&IF(AC3282<>"",VLOOKUP(AC3282,RulesetRef!$A$2:$B$95,2,FALSE()),"")&","&AD3282&","&AE3282&","&IF(AF3282<>"",AF3282,"false"))
E3283: =IF(AND(A3283="",D3283=""),"",IF(OR(AND(ISNUMBER(SEARCH("@",A3283))*ISNUMBER(SEARCH(".",A3283,SEARCH("@",A3283))),ISBLANK(D3283)),LEN(D3283)>=8),1,0)) | I3283: =IF(H3283="","",H3283) | AG3283: =IF(ISNUMBER(SEARCH(B3283,D3283)), 0, 1) -> 1 | AH3283: =IF(ISNUMBER(SEARCH(C3283,D3283)), 0, 1) -> 1 | AI3283: =IF(ISNUMBER(SEARCH(A3283,D3283)), 0, 1) -> 1 | AJ3283: =IF(A3283="","User Name Missing",IF(B3283="","First Name Missing",IF(C3283="","Last Name Missing",IF(E3283=0,"Password Short(Min 8 Charcters)",IF(AG3283=0,"The password cannot contain the user's first name.",IF(AH3283=0,"The password cannot contain the user's last name.",IF(AI3283=0,"The password cannot contain the username.",IF(F3283="","Group Missing",IF(J3283="","Security Clearance Missing",IF(R3283="","Fuel Economy Measurement missing",IF(S3283="","Distance Measurement System missing",IF(T3283="","Feature Preview missing",IF(U3283="","Time Zone Missing",IF(AD3283="","Yard Move allowed Missing",IF(AE3283="","Personal Conveyance Missing","Good"))))))))))))))) -> User Name Missing | AK3283: =IF(AJ3283<>"Good","",A3283&","&B3283&","&C3283&","&D3283&","&F3283&","&H3283&","&J3283&","&K3283&","&L3283&","&M3283&","&N3283&","&O3283&","&P3283&","&Q3283&","&IF(R3283<>"",VLOOKUP(R3283,'Vlookup''sRef'!$C$3:$D$6,2,FALSE()),"")&","&IF(S3283<>"",VLOOKUP(S3283,'Vlookup''sRef'!$F$3:$G$4,2,FALSE()),"")&","&T3283&","&U3283&","&V3283&","&W3283&","&X3283&","&Y3283&","&Z3283&","&AA3283&","&IF(AB3283<>"",VLOOKUP(AB3283,'Vlookup''sRef'!$O$2:$P$101,2,FALSE()),"")&","&IF(AC3283<>"",VLOOKUP(AC3283,RulesetRef!$A$2:$B$95,2,FALSE()),"")&","&AD3283&","&AE3283&","&IF(AF3283<>"",AF3283,"false"))
E3284: =IF(AND(A3284="",D3284=""),"",IF(OR(AND(ISNUMBER(SEARCH("@",A3284))*ISNUMBER(SEARCH(".",A3284,SEARCH("@",A3284))),ISBLANK(D3284)),LEN(D3284)>=8),1,0)) | I3284: =IF(H3284="","",H3284) | AG3284: =IF(ISNUMBER(SEARCH(B3284,D3284)), 0, 1) -> 1 | AH3284: =IF(ISNUMBER(SEARCH(C3284,D3284)), 0, 1) -> 1 | AI3284: =IF(ISNUMBER(SEARCH(A3284,D3284)), 0, 1) -> 1 | AJ3284: =IF(A3284="","User Name Missing",IF(B3284="","First Name Missing",IF(C3284="","Last Name Missing",IF(E3284=0,"Password Short(Min 8 Charcters)",IF(AG3284=0,"The password cannot contain the user's first name.",IF(AH3284=0,"The password cannot contain the user's last name.",IF(AI3284=0,"The password cannot contain the username.",IF(F3284="","Group Missing",IF(J3284="","Security Clearance Missing",IF(R3284="","Fuel Economy Measurement missing",IF(S3284="","Distance Measurement System missing",IF(T3284="","Feature Preview missing",IF(U3284="","Time Zone Missing",IF(AD3284="","Yard Move allowed Missing",IF(AE3284="","Personal Conveyance Missing","Good"))))))))))))))) -> User Name Missing | AK3284: =IF(AJ3284<>"Good","",A3284&","&B3284&","&C3284&","&D3284&","&F3284&","&H3284&","&J3284&","&K3284&","&L3284&","&M3284&","&N3284&","&O3284&","&P3284&","&Q3284&","&IF(R3284<>"",VLOOKUP(R3284,'Vlookup''sRef'!$C$3:$D$6,2,FALSE()),"")&","&IF(S3284<>"",VLOOKUP(S3284,'Vlookup''sRef'!$F$3:$G$4,2,FALSE()),"")&","&T3284&","&U3284&","&V3284&","&W3284&","&X3284&","&Y3284&","&Z3284&","&AA3284&","&IF(AB3284<>"",VLOOKUP(AB3284,'Vlookup''sRef'!$O$2:$P$101,2,FALSE()),"")&","&IF(AC3284<>"",VLOOKUP(AC3284,RulesetRef!$A$2:$B$95,2,FALSE()),"")&","&AD3284&","&AE3284&","&IF(AF3284<>"",AF3284,"false"))
E3285: =IF(AND(A3285="",D3285=""),"",IF(OR(AND(ISNUMBER(SEARCH("@",A3285))*ISNUMBER(SEARCH(".",A3285,SEARCH("@",A3285))),ISBLANK(D3285)),LEN(D3285)>=8),1,0)) | I3285: =IF(H3285="","",H3285) | AG3285: =IF(ISNUMBER(SEARCH(B3285,D3285)), 0, 1) -> 1 | AH3285: =IF(ISNUMBER(SEARCH(C3285,D3285)), 0, 1) -> 1 | AI3285: =IF(ISNUMBER(SEARCH(A3285,D3285)), 0, 1) -> 1 | AJ3285: =IF(A3285="","User Name Missing",IF(B3285="","First Name Missing",IF(C3285="","Last Name Missing",IF(E3285=0,"Password Short(Min 8 Charcters)",IF(AG3285=0,"The password cannot contain the user's first name.",IF(AH3285=0,"The password cannot contain the user's last name.",IF(AI3285=0,"The password cannot contain the username.",IF(F3285="","Group Missing",IF(J3285="","Security Clearance Missing",IF(R3285="","Fuel Economy Measurement missing",IF(S3285="","Distance Measurement System missing",IF(T3285="","Feature Preview missing",IF(U3285="","Time Zone Missing",IF(AD3285="","Yard Move allowed Missing",IF(AE3285="","Personal Conveyance Missing","Good"))))))))))))))) -> User Name Missing | AK3285: =IF(AJ3285<>"Good","",A3285&","&B3285&","&C3285&","&D3285&","&F3285&","&H3285&","&J3285&","&K3285&","&L3285&","&M3285&","&N3285&","&O3285&","&P3285&","&Q3285&","&IF(R3285<>"",VLOOKUP(R3285,'Vlookup''sRef'!$C$3:$D$6,2,FALSE()),"")&","&IF(S3285<>"",VLOOKUP(S3285,'Vlookup''sRef'!$F$3:$G$4,2,FALSE()),"")&","&T3285&","&U3285&","&V3285&","&W3285&","&X3285&","&Y3285&","&Z3285&","&AA3285&","&IF(AB3285<>"",VLOOKUP(AB3285,'Vlookup''sRef'!$O$2:$P$101,2,FALSE()),"")&","&IF(AC3285<>"",VLOOKUP(AC3285,RulesetRef!$A$2:$B$95,2,FALSE()),"")&","&AD3285&","&AE3285&","&IF(AF3285<>"",AF3285,"false"))
E3286: =IF(AND(A3286="",D3286=""),"",IF(OR(AND(ISNUMBER(SEARCH("@",A3286))*ISNUMBER(SEARCH(".",A3286,SEARCH("@",A3286))),ISBLANK(D3286)),LEN(D3286)>=8),1,0)) | I3286: =IF(H3286="","",H3286) | AG3286: =IF(ISNUMBER(SEARCH(B3286,D3286)), 0, 1) -> 1 | AH3286: =IF(ISNUMBER(SEARCH(C3286,D3286)), 0, 1) -> 1 | AI3286: =IF(ISNUMBER(SEARCH(A3286,D3286)), 0, 1) -> 1 | AJ3286: =IF(A3286="","User Name Missing",IF(B3286="","First Name Missing",IF(C3286="","Last Name Missing",IF(E3286=0,"Password Short(Min 8 Charcters)",IF(AG3286=0,"The password cannot contain the user's first name.",IF(AH3286=0,"The password cannot contain the user's last name.",IF(AI3286=0,"The password cannot contain the username.",IF(F3286="","Group Missing",IF(J3286="","Security Clearance Missing",IF(R3286="","Fuel Economy Measurement missing",IF(S3286="","Distance Measurement System missing",IF(T3286="","Feature Preview missing",IF(U3286="","Time Zone Missing",IF(AD3286="","Yard Move allowed Missing",IF(AE3286="","Personal Conveyance Missing","Good"))))))))))))))) -> User Name Missing | AK3286: =IF(AJ3286<>"Good","",A3286&","&B3286&","&C3286&","&D3286&","&F3286&","&H3286&","&J3286&","&K3286&","&L3286&","&M3286&","&N3286&","&O3286&","&P3286&","&Q3286&","&IF(R3286<>"",VLOOKUP(R3286,'Vlookup''sRef'!$C$3:$D$6,2,FALSE()),"")&","&IF(S3286<>"",VLOOKUP(S3286,'Vlookup''sRef'!$F$3:$G$4,2,FALSE()),"")&","&T3286&","&U3286&","&V3286&","&W3286&","&X3286&","&Y3286&","&Z3286&","&AA3286&","&IF(AB3286<>"",VLOOKUP(AB3286,'Vlookup''sRef'!$O$2:$P$101,2,FALSE()),"")&","&IF(AC3286<>"",VLOOKUP(AC3286,RulesetRef!$A$2:$B$95,2,FALSE()),"")&","&AD3286&","&AE3286&","&IF(AF3286<>"",AF3286,"false"))
E3287: =IF(AND(A3287="",D3287=""),"",IF(OR(AND(ISNUMBER(SEARCH("@",A3287))*ISNUMBER(SEARCH(".",A3287,SEARCH("@",A3287))),ISBLANK(D3287)),LEN(D3287)>=8),1,0)) | I3287: =IF(H3287="","",H3287) | AG3287: =IF(ISNUMBER(SEARCH(B3287,D3287)), 0, 1) -> 1 | AH3287: =IF(ISNUMBER(SEARCH(C3287,D3287)), 0, 1) -> 1 | AI3287: =IF(ISNUMBER(SEARCH(A3287,D3287)), 0, 1) -> 1 | AJ3287: =IF(A3287="","User Name Missing",IF(B3287="","First Name Missing",IF(C3287="","Last Name Missing",IF(E3287=0,"Password Short(Min 8 Charcters)",IF(AG3287=0,"The password cannot contain the user's first name.",IF(AH3287=0,"The password cannot contain the user's last name.",IF(AI3287=0,"The password cannot contain the username.",IF(F3287="","Group Missing",IF(J3287="","Security Clearance Missing",IF(R3287="","Fuel Economy Measurement missing",IF(S3287="","Distance Measurement System missing",IF(T3287="","Feature Preview missing",IF(U3287="","Time Zone Missing",IF(AD3287="","Yard Move allowed Missing",IF(AE3287="","Personal Conveyance Missing","Good"))))))))))))))) -> User Name Missing | AK3287: =IF(AJ3287<>"Good","",A3287&","&B3287&","&C3287&","&D3287&","&F3287&","&H3287&","&J3287&","&K3287&","&L3287&","&M3287&","&N3287&","&O3287&","&P3287&","&Q3287&","&IF(R3287<>"",VLOOKUP(R3287,'Vlookup''sRef'!$C$3:$D$6,2,FALSE()),"")&","&IF(S3287<>"",VLOOKUP(S3287,'Vlookup''sRef'!$F$3:$G$4,2,FALSE()),"")&","&T3287&","&U3287&","&V3287&","&W3287&","&X3287&","&Y3287&","&Z3287&","&AA3287&","&IF(AB3287<>"",VLOOKUP(AB3287,'Vlookup''sRef'!$O$2:$P$101,2,FALSE()),"")&","&IF(AC3287<>"",VLOOKUP(AC3287,RulesetRef!$A$2:$B$95,2,FALSE()),"")&","&AD3287&","&AE3287&","&IF(AF3287<>"",AF3287,"false"))
E3288: =IF(AND(A3288="",D3288=""),"",IF(OR(AND(ISNUMBER(SEARCH("@",A3288))*ISNUMBER(SEARCH(".",A3288,SEARCH("@",A3288))),ISBLANK(D3288)),LEN(D3288)>=8),1,0)) | I3288: =IF(H3288="","",H3288) | AG3288: =IF(ISNUMBER(SEARCH(B3288,D3288)), 0, 1) -> 1 | AH3288: =IF(ISNUMBER(SEARCH(C3288,D3288)), 0, 1) -> 1 | AI3288: =IF(ISNUMBER(SEARCH(A3288,D3288)), 0, 1) -> 1 | AJ3288: =IF(A3288="","User Name Missing",IF(B3288="","First Name Missing",IF(C3288="","Last Name Missing",IF(E3288=0,"Password Short(Min 8 Charcters)",IF(AG3288=0,"The password cannot contain the user's first name.",IF(AH3288=0,"The password cannot contain the user's last name.",IF(AI3288=0,"The password cannot contain the username.",IF(F3288="","Group Missing",IF(J3288="","Security Clearance Missing",IF(R3288="","Fuel Economy Measurement missing",IF(S3288="","Distance Measurement System missing",IF(T3288="","Feature Preview missing",IF(U3288="","Time Zone Missing",IF(AD3288="","Yard Move allowed Missing",IF(AE3288="","Personal Conveyance Missing","Good"))))))))))))))) -> User Name Missing | AK3288: =IF(AJ3288<>"Good","",A3288&","&B3288&","&C3288&","&D3288&","&F3288&","&H3288&","&J3288&","&K3288&","&L3288&","&M3288&","&N3288&","&O3288&","&P3288&","&Q3288&","&IF(R3288<>"",VLOOKUP(R3288,'Vlookup''sRef'!$C$3:$D$6,2,FALSE()),"")&","&IF(S3288<>"",VLOOKUP(S3288,'Vlookup''sRef'!$F$3:$G$4,2,FALSE()),"")&","&T3288&","&U3288&","&V3288&","&W3288&","&X3288&","&Y3288&","&Z3288&","&AA3288&","&IF(AB3288<>"",VLOOKUP(AB3288,'Vlookup''sRef'!$O$2:$P$101,2,FALSE()),"")&","&IF(AC3288<>"",VLOOKUP(AC3288,RulesetRef!$A$2:$B$95,2,FALSE()),"")&","&AD3288&","&AE3288&","&IF(AF3288<>"",AF3288,"false"))
E3289: =IF(AND(A3289="",D3289=""),"",IF(OR(AND(ISNUMBER(SEARCH("@",A3289))*ISNUMBER(SEARCH(".",A3289,SEARCH("@",A3289))),ISBLANK(D3289)),LEN(D3289)>=8),1,0)) | I3289: =IF(H3289="","",H3289) | AG3289: =IF(ISNUMBER(SEARCH(B3289,D3289)), 0, 1) -> 1 | AH3289: =IF(ISNUMBER(SEARCH(C3289,D3289)), 0, 1) -> 1 | AI3289: =IF(ISNUMBER(SEARCH(A3289,D3289)), 0, 1) -> 1 | AJ3289: =IF(A3289="","User Name Missing",IF(B3289="","First Name Missing",IF(C3289="","Last Name Missing",IF(E3289=0,"Password Short(Min 8 Charcters)",IF(AG3289=0,"The password cannot contain the user's first name.",IF(AH3289=0,"The password cannot contain the user's last name.",IF(AI3289=0,"The password cannot contain the username.",IF(F3289="","Group Missing",IF(J3289="","Security Clearance Missing",IF(R3289="","Fuel Economy Measurement missing",IF(S3289="","Distance Measurement System missing",IF(T3289="","Feature Preview missing",IF(U3289="","Time Zone Missing",IF(AD3289="","Yard Move allowed Missing",IF(AE3289="","Personal Conveyance Missing","Good"))))))))))))))) -> User Name Missing | AK3289: =IF(AJ3289<>"Good","",A3289&","&B3289&","&C3289&","&D3289&","&F3289&","&H3289&","&J3289&","&K3289&","&L3289&","&M3289&","&N3289&","&O3289&","&P3289&","&Q3289&","&IF(R3289<>"",VLOOKUP(R3289,'Vlookup''sRef'!$C$3:$D$6,2,FALSE()),"")&","&IF(S3289<>"",VLOOKUP(S3289,'Vlookup''sRef'!$F$3:$G$4,2,FALSE()),"")&","&T3289&","&U3289&","&V3289&","&W3289&","&X3289&","&Y3289&","&Z3289&","&AA3289&","&IF(AB3289<>"",VLOOKUP(AB3289,'Vlookup''sRef'!$O$2:$P$101,2,FALSE()),"")&","&IF(AC3289<>"",VLOOKUP(AC3289,RulesetRef!$A$2:$B$95,2,FALSE()),"")&","&AD3289&","&AE3289&","&IF(AF3289<>"",AF3289,"false"))
E3290: =IF(AND(A3290="",D3290=""),"",IF(OR(AND(ISNUMBER(SEARCH("@",A3290))*ISNUMBER(SEARCH(".",A3290,SEARCH("@",A3290))),ISBLANK(D3290)),LEN(D3290)>=8),1,0)) | I3290: =IF(H3290="","",H3290) | AG3290: =IF(ISNUMBER(SEARCH(B3290,D3290)), 0, 1) -> 1 | AH3290: =IF(ISNUMBER(SEARCH(C3290,D3290)), 0, 1) -> 1 | AI3290: =IF(ISNUMBER(SEARCH(A3290,D3290)), 0, 1) -> 1 | AJ3290: =IF(A3290="","User Name Missing",IF(B3290="","First Name Missing",IF(C3290="","Last Name Missing",IF(E3290=0,"Password Short(Min 8 Charcters)",IF(AG3290=0,"The password cannot contain the user's first name.",IF(AH3290=0,"The password cannot contain the user's last name.",IF(AI3290=0,"The password cannot contain the username.",IF(F3290="","Group Missing",IF(J3290="","Security Clearance Missing",IF(R3290="","Fuel Economy Measurement missing",IF(S3290="","Distance Measurement System missing",IF(T3290="","Feature Preview missing",IF(U3290="","Time Zone Missing",IF(AD3290="","Yard Move allowed Missing",IF(AE3290="","Personal Conveyance Missing","Good"))))))))))))))) -> User Name Missing | AK3290: =IF(AJ3290<>"Good","",A3290&","&B3290&","&C3290&","&D3290&","&F3290&","&H3290&","&J3290&","&K3290&","&L3290&","&M3290&","&N3290&","&O3290&","&P3290&","&Q3290&","&IF(R3290<>"",VLOOKUP(R3290,'Vlookup''sRef'!$C$3:$D$6,2,FALSE()),"")&","&IF(S3290<>"",VLOOKUP(S3290,'Vlookup''sRef'!$F$3:$G$4,2,FALSE()),"")&","&T3290&","&U3290&","&V3290&","&W3290&","&X3290&","&Y3290&","&Z3290&","&AA3290&","&IF(AB3290<>"",VLOOKUP(AB3290,'Vlookup''sRef'!$O$2:$P$101,2,FALSE()),"")&","&IF(AC3290<>"",VLOOKUP(AC3290,RulesetRef!$A$2:$B$95,2,FALSE()),"")&","&AD3290&","&AE3290&","&IF(AF3290<>"",AF3290,"false"))
E3291: =IF(AND(A3291="",D3291=""),"",IF(OR(AND(ISNUMBER(SEARCH("@",A3291))*ISNUMBER(SEARCH(".",A3291,SEARCH("@",A3291))),ISBLANK(D3291)),LEN(D3291)>=8),1,0)) | I3291: =IF(H3291="","",H3291) | AG3291: =IF(ISNUMBER(SEARCH(B3291,D3291)), 0, 1) -> 1 | AH3291: =IF(ISNUMBER(SEARCH(C3291,D3291)), 0, 1) -> 1 | AI3291: =IF(ISNUMBER(SEARCH(A3291,D3291)), 0, 1) -> 1 | AJ3291: =IF(A3291="","User Name Missing",IF(B3291="","First Name Missing",IF(C3291="","Last Name Missing",IF(E3291=0,"Password Short(Min 8 Charcters)",IF(AG3291=0,"The password cannot contain the user's first name.",IF(AH3291=0,"The password cannot contain the user's last name.",IF(AI3291=0,"The password cannot contain the username.",IF(F3291="","Group Missing",IF(J3291="","Security Clearance Missing",IF(R3291="","Fuel Economy Measurement missing",IF(S3291="","Distance Measurement System missing",IF(T3291="","Feature Preview missing",IF(U3291="","Time Zone Missing",IF(AD3291="","Yard Move allowed Missing",IF(AE3291="","Personal Conveyance Missing","Good"))))))))))))))) -> User Name Missing | AK3291: =IF(AJ3291<>"Good","",A3291&","&B3291&","&C3291&","&D3291&","&F3291&","&H3291&","&J3291&","&K3291&","&L3291&","&M3291&","&N3291&","&O3291&","&P3291&","&Q3291&","&IF(R3291<>"",VLOOKUP(R3291,'Vlookup''sRef'!$C$3:$D$6,2,FALSE()),"")&","&IF(S3291<>"",VLOOKUP(S3291,'Vlookup''sRef'!$F$3:$G$4,2,FALSE()),"")&","&T3291&","&U3291&","&V3291&","&W3291&","&X3291&","&Y3291&","&Z3291&","&AA3291&","&IF(AB3291<>"",VLOOKUP(AB3291,'Vlookup''sRef'!$O$2:$P$101,2,FALSE()),"")&","&IF(AC3291<>"",VLOOKUP(AC3291,RulesetRef!$A$2:$B$95,2,FALSE()),"")&","&AD3291&","&AE3291&","&IF(AF3291<>"",AF3291,"false"))
E3292: =IF(AND(A3292="",D3292=""),"",IF(OR(AND(ISNUMBER(SEARCH("@",A3292))*ISNUMBER(SEARCH(".",A3292,SEARCH("@",A3292))),ISBLANK(D3292)),LEN(D3292)>=8),1,0)) | I3292: =IF(H3292="","",H3292) | AG3292: =IF(ISNUMBER(SEARCH(B3292,D3292)), 0, 1) -> 1 | AH3292: =IF(ISNUMBER(SEARCH(C3292,D3292)), 0, 1) -> 1 | AI3292: =IF(ISNUMBER(SEARCH(A3292,D3292)), 0, 1) -> 1 | AJ3292: =IF(A3292="","User Name Missing",IF(B3292="","First Name Missing",IF(C3292="","Last Name Missing",IF(E3292=0,"Password Short(Min 8 Charcters)",IF(AG3292=0,"The password cannot contain the user's first name.",IF(AH3292=0,"The password cannot contain the user's last name.",IF(AI3292=0,"The password cannot contain the username.",IF(F3292="","Group Missing",IF(J3292="","Security Clearance Missing",IF(R3292="","Fuel Economy Measurement missing",IF(S3292="","Distance Measurement System missing",IF(T3292="","Feature Preview missing",IF(U3292="","Time Zone Missing",IF(AD3292="","Yard Move allowed Missing",IF(AE3292="","Personal Conveyance Missing","Good"))))))))))))))) -> User Name Missing | AK3292: =IF(AJ3292<>"Good","",A3292&","&B3292&","&C3292&","&D3292&","&F3292&","&H3292&","&J3292&","&K3292&","&L3292&","&M3292&","&N3292&","&O3292&","&P3292&","&Q3292&","&IF(R3292<>"",VLOOKUP(R3292,'Vlookup''sRef'!$C$3:$D$6,2,FALSE()),"")&","&IF(S3292<>"",VLOOKUP(S3292,'Vlookup''sRef'!$F$3:$G$4,2,FALSE()),"")&","&T3292&","&U3292&","&V3292&","&W3292&","&X3292&","&Y3292&","&Z3292&","&AA3292&","&IF(AB3292<>"",VLOOKUP(AB3292,'Vlookup''sRef'!$O$2:$P$101,2,FALSE()),"")&","&IF(AC3292<>"",VLOOKUP(AC3292,RulesetRef!$A$2:$B$95,2,FALSE()),"")&","&AD3292&","&AE3292&","&IF(AF3292<>"",AF3292,"false"))
E3293: =IF(AND(A3293="",D3293=""),"",IF(OR(AND(ISNUMBER(SEARCH("@",A3293))*ISNUMBER(SEARCH(".",A3293,SEARCH("@",A3293))),ISBLANK(D3293)),LEN(D3293)>=8),1,0)) | I3293: =IF(H3293="","",H3293) | AG3293: =IF(ISNUMBER(SEARCH(B3293,D3293)), 0, 1) -> 1 | AH3293: =IF(ISNUMBER(SEARCH(C3293,D3293)), 0, 1) -> 1 | AI3293: =IF(ISNUMBER(SEARCH(A3293,D3293)), 0, 1) -> 1 | AJ3293: =IF(A3293="","User Name Missing",IF(B3293="","First Name Missing",IF(C3293="","Last Name Missing",IF(E3293=0,"Password Short(Min 8 Charcters)",IF(AG3293=0,"The password cannot contain the user's first name.",IF(AH3293=0,"The password cannot contain the user's last name.",IF(AI3293=0,"The password cannot contain the username.",IF(F3293="","Group Missing",IF(J3293="","Security Clearance Missing",IF(R3293="","Fuel Economy Measurement missing",IF(S3293="","Distance Measurement System missing",IF(T3293="","Feature Preview missing",IF(U3293="","Time Zone Missing",IF(AD3293="","Yard Move allowed Missing",IF(AE3293="","Personal Conveyance Missing","Good"))))))))))))))) -> User Name Missing | AK3293: =IF(AJ3293<>"Good","",A3293&","&B3293&","&C3293&","&D3293&","&F3293&","&H3293&","&J3293&","&K3293&","&L3293&","&M3293&","&N3293&","&O3293&","&P3293&","&Q3293&","&IF(R3293<>"",VLOOKUP(R3293,'Vlookup''sRef'!$C$3:$D$6,2,FALSE()),"")&","&IF(S3293<>"",VLOOKUP(S3293,'Vlookup''sRef'!$F$3:$G$4,2,FALSE()),"")&","&T3293&","&U3293&","&V3293&","&W3293&","&X3293&","&Y3293&","&Z3293&","&AA3293&","&IF(AB3293<>"",VLOOKUP(AB3293,'Vlookup''sRef'!$O$2:$P$101,2,FALSE()),"")&","&IF(AC3293<>"",VLOOKUP(AC3293,RulesetRef!$A$2:$B$95,2,FALSE()),"")&","&AD3293&","&AE3293&","&IF(AF3293<>"",AF3293,"false"))
... E4048: =IF(AND(A4048="",D4048=""),"",IF(OR(AND(ISNUMBER(SEARCH("@",A4048))*ISNUMBER(SEARCH(".",A4048,SEARCH("@",A4048))),ISBLANK(D4048)),LEN(D4048)>=8),1,0)) | I4048: =IF(H4048="","",H4048) | AG4048: =IF(ISNUMBER(SEARCH(B4048,D4048)), 0, 1) -> 1 | AH4048: =IF(ISNUMBER(SEARCH(C4048,D4048)), 0, 1) -> 1 | AI4048: =IF(ISNUMBER(SEARCH(A4048,D4048)), 0, 1) -> 1 | AJ4048: =IF(A4048="","User Name Missing",IF(B4048="","First Name Missing",IF(C4048="","Last Name Missing",IF(E4048=0,"Password Short(Min 8 Charcters)",IF(AG4048=0,"The password cannot contain the user's first name.",IF(AH4048=0,"The password cannot contain the user's last name.",IF(AI4048=0,"The password cannot contain the username.",IF(F4048="","Group Missing",IF(J4048="","Security Clearance Missing",IF(R4048="","Fuel Economy Measurement missing",IF(S4048="","Distance Measurement System missing",IF(T4048="","Feature Preview missing",IF(U4048="","Time Zone Missing",IF(AD4048="","Yard Move allowed Missing",IF(AE4048="","Personal Conveyance Missing","Good"))))))))))))))) -> User Name Missing | AK4048: =IF(AJ4048<>"Good","",A4048&","&B4048&","&C4048&","&D4048&","&F4048&","&H4048&","&J4048&","&K4048&","&L4048&","&M4048&","&N4048&","&O4048&","&P4048&","&Q4048&","&IF(R4048<>"",VLOOKUP(R4048,'Vlookup''sRef'!$C$3:$D$6,2,FALSE()),"")&","&IF(S4048<>"",VLOOKUP(S4048,'Vlookup''sRef'!$F$3:$G$4,2,FALSE()),"")&","&T4048&","&U4048&","&V4048&","&W4048&","&X4048&","&Y4048&","&Z4048&","&AA4048&","&IF(AB4048<>"",VLOOKUP(AB4048,'Vlookup''sRef'!$O$2:$P$101,2,FALSE()),"")&","&IF(AC4048<>"",VLOOKUP(AC4048,RulesetRef!$A$2:$B$95,2,FALSE()),"")&","&AD4048&","&AE4048&","&IF(AF4048<>"",AF4048,"false"))

Sheet Vlookup'sRef
O1: Provincial Codes | R1: Country Codes
C2: Fuel economy measurement | F2: Distance measurement system | J2: Time Zones | L2: Good | O2: Aguascalientes | P2: AG | R2: Canada | S2: CA
A3: true | C3: L/100 km | D3: LitersPer100Km | F3: Metric | G3: true | J3: Africa/Abidjan | L3: User Name Missing | O3: Alabama | P3: AL | R3: United States | S3: US
A4: false | C4: km/L | D4: KmPerLiter | F4: US/Imperial | G4: false | J4: Africa/Accra | L4: First Name Missing | O4: Alaska | P4: AK | R4: Albania | S4: AL
C5: MPG (US) | D5: MPGUS | J5: Africa/Addis_Ababa | L5: Last Name Missing | O5: Alberta | P5: AB | R5: Andorra | S5: AD
C6: MPG (Imp) | D6: MPGImperial | J6: Africa/Algiers | L6: Password Short(Min 8 Characters) | O6: American Samoa | P6: AS | R6: Angola | S6: AO
J7: Africa/Asmera | L7: Group Missing | O7: Arizona | P7: AZ | R7: Argentina | S7: AR
J8: Africa/Bamako | L8: Security Clearance Missing | O8: Arkansas | P8: AR | R8: Armenia | S8: AM
J9: Africa/Bangui | L9: Feature Preview Missing | O9: Baja California Norte | P9: BN | R9: Australia | S9: AU
J10: Africa/Banjul | L10: Time Zone Missing | O10: Baja California Sur | P10: BS | R10: Austria | S10: AT
J11: Africa/Bissau | L11: Yard Move Allowed Missing | O11: British Columbia | P11: BC | R11: Azerbaijan | S11: AZ
J12: Africa/Blantyre | L12: Personal Conveyance Missing | O12: California | P12: CA | R12: Bahamas | S12: BS
J13: Africa/Brazzaville | L13: The password cannot contain the user's first name. | O13: Campeche | P13: CP | R13: Bahrain | S13: BH
J14: Africa/Bujumbura | L14: The password cannot contain the user's last name. | O14: Chiapas | P14: CS | R14: Bangladesh | S14: BD
J15: Africa/Cairo | L15: The password cannot contain the username. | O15: Chihuahua | P15: CI | R15: Belarus | S15: BY
J16: Africa/Casablanca | O16: Coahuila | P16: CH | R16: Belgium | S16: BE
J17: Africa/Ceuta | O17: Colima | P17: CL | R17: Belize | S17: BZ
J18: Africa/Conakry | O18: Colorado | P18: CO | R18: Bhutan | S18: BT
J19: Africa/Dakar | O19: Connecticut | P19: CT | R19: Bolivia | S19: BO
J20: Africa/Dar_es_Salaam | O20: Delaware | P20: DE | R20: Bosnia and Herzegovina | S20: BA
J21: Africa/Djibouti | O21: Dist of col | P21: DC | R21: Botswana | S21: BW
J22: Africa/Douala | O22: Districto Federal | P22: DF | R22: Brazil | S22: BR
J23: Africa/El_Aaiun | O23: Durango | P23: DG | R23: Bulgaria | S23: BG
J24: Africa/Freetown | O24: Florida | P24: FL | R24: Burkina Faso | S24: BF
J25: Africa/Gaborone | O25: Georgia | P25: GA | R25: Cambodia | S25: KH
J26: Africa/Harare | O26: Guam | P26: GU | R26: Cameroon | S26: CM
J27: Africa/Johannesburg | O27: Guanajuato | P27: GJ | R27: Central African Republic | S27: CF
... J101: America/El_Salvador | O101: Zacatecas | P101: ZA | R101: Niger | S101: NE
J102: America/Fort_Nelson | R102: Nigeria | S102: NG
J103: America/Fortaleza | R103: Norway | S103: NO
J104: America/Glace_Bay | R104: Oman | S104: OM
J105: America/Godthab | R105: Panama | S105: PA
J106: America/Goose_Bay | R106: Papua New Guinea | S106: PG
J107: America/Grand_Turk | R107: Paraguay | S107: PY
J108: America/Grenada | R108: Peru | S108: PE
J109: America/Guadeloupe | R109: Philippines | S109: PH
J110: America/Guatemala | R110: Poland | S110: PL
J111: America/Guayaquil | R111: Portugal | S111: PT
J112: America/Guyana | R112: Puerto Rico | S112: PR
J113: America/Halifax | R113: Qatar | S113: QA
...

Sheet RulesetRef
A1: Ruleset Label | B1: Ruleset Value
A2: Alaska Passenger 70-hour/7-day | B2: HosRuleSetAlaskaPassenger7Day
A3: Alaska Passenger 80-hour/8-day | B3: HosRuleSetAlaskaPassenger8Day
A4: Alaska Property 70-hour/7-day | B4: HosRuleSetAlaskaProperty7Day
A5: Alaska Property 70-hour/7-day with split sleeper | B5: HosRuleSetAlaskaProperty7DaySleeper
A6: Alaska Property 80-hour/8-day | B6: HosRuleSetAlaskaProperty8Day
A7: Alaska Property 80-hour/8-day with split sleeper | B7: HosRuleSetAlaskaProperty8DaySleeper
A8: Alberta | B8: HosRuleSetAlberta
A9: Australia Standard Hours Solo with Exemption Hours | B9: HosRuleSetAustraliaStandardHoursSoloExemptionHours
A10: BC Logging Truck | B10: HosRuleSetCanadaBCLoggingTruck
A11: Brazil Property Short-haul | B11: HosRuleSetBrazilShortHaul
A12: California Farm Product | B12: HosRuleSetCaliforniaFarmProduct
... A95: Washington Intrastate Logging/Dumptruck 90-hour/8-day | B95: HosRuleSetWashingtonIntrastate8Day
